[2025-03-14T18:20:55.635+0000] {local_task_job_runner.py:123} INFO - ::group::Pre task execution logs
[2025-03-14T18:20:55.646+0000] {taskinstance.py:2614} INFO - Dependencies all met for dep_context=non-requeueable deps ti=<TaskInstance: open_weather_etl.extract manual__2025-03-14T18:20:54.725294+00:00 [queued]>
[2025-03-14T18:20:55.778+0000] {taskinstance.py:2614} INFO - Dependencies all met for dep_context=requeueable deps ti=<TaskInstance: open_weather_etl.extract manual__2025-03-14T18:20:54.725294+00:00 [queued]>
[2025-03-14T18:20:55.778+0000] {taskinstance.py:2867} INFO - Starting attempt 1 of 2
[2025-03-14T18:20:55.783+0000] {taskinstance.py:2890} INFO - Executing <Task(PythonOperator): extract> on 2025-03-14 18:20:54.725294+00:00
[2025-03-14T18:20:55.790+0000] {warnings.py:112} WARNING - /home/***/.local/lib/python3.12/site-packages/***/task/task_runner/standard_task_runner.py:70: DeprecationWarning: This process (pid=119) is multi-threaded, use of fork() may lead to deadlocks in the child.
  pid = os.fork()

[2025-03-14T18:20:55.791+0000] {standard_task_runner.py:72} INFO - Started process 120 to run task
[2025-03-14T18:20:55.791+0000] {standard_task_runner.py:104} INFO - Running: ['***', 'tasks', 'run', 'open_weather_etl', 'extract', 'manual__2025-03-14T18:20:54.725294+00:00', '--job-id', '58', '--raw', '--subdir', 'DAGS_FOLDER/open_weather_dag.py', '--cfg-path', '/tmp/tmp4s01vcxp']
[2025-03-14T18:20:55.792+0000] {standard_task_runner.py:105} INFO - Job 58: Subtask extract
[2025-03-14T18:20:55.811+0000] {task_command.py:467} INFO - Running <TaskInstance: open_weather_etl.extract manual__2025-03-14T18:20:54.725294+00:00 [running]> on host a8e3300004fc
[2025-03-14T18:20:55.841+0000] {taskinstance.py:3134} INFO - Exporting env vars: AIRFLOW_CTX_DAG_EMAIL='lherrera5034@gmail.com' AIRFLOW_CTX_DAG_OWNER='Airflow' AIRFLOW_CTX_DAG_ID='open_weather_etl' AIRFLOW_CTX_TASK_ID='extract' AIRFLOW_CTX_EXECUTION_DATE='2025-03-14T18:20:54.725294+00:00' AIRFLOW_CTX_TRY_NUMBER='1' AIRFLOW_CTX_DAG_RUN_ID='manual__2025-03-14T18:20:54.725294+00:00'
[2025-03-14T18:20:55.842+0000] {taskinstance.py:732} INFO - ::endgroup::
[2025-03-14T18:20:55.852+0000] {taskinstance.py:3313} ERROR - Task failed with exception
Traceback (most recent call last):
  File "/home/airflow/.local/lib/python3.12/site-packages/airflow/models/taskinstance.py", line 768, in _execute_task
    result = _execute_callable(context=context, **execute_callable_kwargs)
             ^^^^^^^^^^^^^^^^^^^^^^^^^^^^^^^^^^^^^^^^^^^^^^^^^^^^^^^^^^^^^
  File "/home/airflow/.local/lib/python3.12/site-packages/airflow/models/taskinstance.py", line 734, in _execute_callable
    return ExecutionCallableRunner(
           ^^^^^^^^^^^^^^^^^^^^^^^^
  File "/home/airflow/.local/lib/python3.12/site-packages/airflow/utils/operator_helpers.py", line 252, in run
    return self.func(*args, **kwargs)
           ^^^^^^^^^^^^^^^^^^^^^^^^^^
  File "/home/airflow/.local/lib/python3.12/site-packages/airflow/models/baseoperator.py", line 424, in wrapper
    return func(self, *args, **kwargs)
           ^^^^^^^^^^^^^^^^^^^^^^^^^^^
  File "/home/airflow/.local/lib/python3.12/site-packages/airflow/operators/python.py", line 238, in execute
    return_value = self.execute_callable()
                   ^^^^^^^^^^^^^^^^^^^^^^^
  File "/home/airflow/.local/lib/python3.12/site-packages/airflow/operators/python.py", line 256, in execute_callable
    return runner.run(*self.op_args, **self.op_kwargs)
           ^^^^^^^^^^^^^^^^^^^^^^^^^^^^^^^^^^^^^^^^^^^
  File "/home/airflow/.local/lib/python3.12/site-packages/airflow/utils/operator_helpers.py", line 252, in run
    return self.func(*args, **kwargs)
           ^^^^^^^^^^^^^^^^^^^^^^^^^^
  File "/opt/airflow/dags/open_weather_dag.py", line 35, in extract_data
    data = extract_data()
           ^^^^^^^^^^^^^^
  File "/opt/airflow/dags/open_weather_dag.py", line 35, in extract_data
    data = extract_data()
           ^^^^^^^^^^^^^^
  File "/opt/airflow/dags/open_weather_dag.py", line 35, in extract_data
    data = extract_data()
           ^^^^^^^^^^^^^^
  [Previous line repeated 922 more times]
  File "/opt/airflow/dags/open_weather_dag.py", line 34, in extract_data
    logger.info('Starting extraction...')
  File "/usr/local/lib/python3.12/logging/__init__.py", line 1539, in info
    self._log(INFO, msg, args, **kwargs)
  File "/usr/local/lib/python3.12/logging/__init__.py", line 1682, in _log
    record = self.makeRecord(self.name, level, fn, lno, msg, args,
             ^^^^^^^^^^^^^^^^^^^^^^^^^^^^^^^^^^^^^^^^^^^^^^^^^^^^^
  File "/usr/local/lib/python3.12/logging/__init__.py", line 1651, in makeRecord
    rv = _logRecordFactory(name, level, fn, lno, msg, args, exc_info, func,
         ^^^^^^^^^^^^^^^^^^^^^^^^^^^^^^^^^^^^^^^^^^^^^^^^^^^^^^^^^^^^^^^^^^
  File "/usr/local/lib/python3.12/logging/__init__.py", line 332, in __init__
    self.filename = os.path.basename(pathname)
                    ^^^^^^^^^^^^^^^^^^^^^^^^^^
  File "<frozen posixpath>", line 172, in basename
RecursionError: maximum recursion depth exceeded
[2025-03-14T18:20:55.865+0000] {taskinstance.py:1226} INFO - Marking task as UP_FOR_RETRY. dag_id=open_weather_etl, task_id=extract, run_id=manual__2025-03-14T18:20:54.725294+00:00, execution_date=20250314T182054, start_date=20250314T182055, end_date=20250314T182055
[2025-03-14T18:20:55.878+0000] {taskinstance.py:341} INFO - ::group::Post task execution logs
[2025-03-14T18:20:55.878+0000] {standard_task_runner.py:124} ERROR - Failed to execute job 58 for task extract (maximum recursion depth exceeded; 120)
Traceback (most recent call last):
  File "/home/airflow/.local/lib/python3.12/site-packages/airflow/task/task_runner/standard_task_runner.py", line 117, in _start_by_fork
    ret = args.func(args, dag=self.dag)
          ^^^^^^^^^^^^^^^^^^^^^^^^^^^^^
  File "/home/airflow/.local/lib/python3.12/site-packages/airflow/cli/cli_config.py", line 49, in command
    return func(*args, **kwargs)
           ^^^^^^^^^^^^^^^^^^^^^
  File "/home/airflow/.local/lib/python3.12/site-packages/airflow/utils/cli.py", line 116, in wrapper
    return f(*args, **kwargs)
           ^^^^^^^^^^^^^^^^^^
  File "/home/airflow/.local/lib/python3.12/site-packages/airflow/cli/commands/task_command.py", line 483, in task_run
    task_return_code = _run_task_by_selected_method(args, _dag, ti)
                       ^^^^^^^^^^^^^^^^^^^^^^^^^^^^^^^^^^^^^^^^^^^^
  File "/home/airflow/.local/lib/python3.12/site-packages/airflow/cli/commands/task_command.py", line 256, in _run_task_by_selected_method
    return _run_raw_task(args, ti)
           ^^^^^^^^^^^^^^^^^^^^^^^
  File "/home/airflow/.local/lib/python3.12/site-packages/airflow/cli/commands/task_command.py", line 341, in _run_raw_task
    return ti._run_raw_task(
           ^^^^^^^^^^^^^^^^^
  File "/home/airflow/.local/lib/python3.12/site-packages/airflow/utils/session.py", line 97, in wrapper
    return func(*args, session=session, **kwargs)
           ^^^^^^^^^^^^^^^^^^^^^^^^^^^^^^^^^^^^^^
  File "/home/airflow/.local/lib/python3.12/site-packages/airflow/models/taskinstance.py", line 3006, in _run_raw_task
    return _run_raw_task(
           ^^^^^^^^^^^^^^
  File "/home/airflow/.local/lib/python3.12/site-packages/airflow/models/taskinstance.py", line 274, in _run_raw_task
    TaskInstance._execute_task_with_callbacks(
  File "/home/airflow/.local/lib/python3.12/site-packages/airflow/models/taskinstance.py", line 3161, in _execute_task_with_callbacks
    result = self._execute_task(context, task_orig)
             ^^^^^^^^^^^^^^^^^^^^^^^^^^^^^^^^^^^^^^
  File "/home/airflow/.local/lib/python3.12/site-packages/airflow/models/taskinstance.py", line 3185, in _execute_task
    return _execute_task(self, context, task_orig)
           ^^^^^^^^^^^^^^^^^^^^^^^^^^^^^^^^^^^^^^^
  File "/home/airflow/.local/lib/python3.12/site-packages/airflow/models/taskinstance.py", line 768, in _execute_task
    result = _execute_callable(context=context, **execute_callable_kwargs)
             ^^^^^^^^^^^^^^^^^^^^^^^^^^^^^^^^^^^^^^^^^^^^^^^^^^^^^^^^^^^^^
  File "/home/airflow/.local/lib/python3.12/site-packages/airflow/models/taskinstance.py", line 734, in _execute_callable
    return ExecutionCallableRunner(
           ^^^^^^^^^^^^^^^^^^^^^^^^
  File "/home/airflow/.local/lib/python3.12/site-packages/airflow/utils/operator_helpers.py", line 252, in run
    return self.func(*args, **kwargs)
           ^^^^^^^^^^^^^^^^^^^^^^^^^^
  File "/home/airflow/.local/lib/python3.12/site-packages/airflow/models/baseoperator.py", line 424, in wrapper
    return func(self, *args, **kwargs)
           ^^^^^^^^^^^^^^^^^^^^^^^^^^^
  File "/home/airflow/.local/lib/python3.12/site-packages/airflow/operators/python.py", line 238, in execute
    return_value = self.execute_callable()
                   ^^^^^^^^^^^^^^^^^^^^^^^
  File "/home/airflow/.local/lib/python3.12/site-packages/airflow/operators/python.py", line 256, in execute_callable
    return runner.run(*self.op_args, **self.op_kwargs)
           ^^^^^^^^^^^^^^^^^^^^^^^^^^^^^^^^^^^^^^^^^^^
  File "/home/airflow/.local/lib/python3.12/site-packages/airflow/utils/operator_helpers.py", line 252, in run
    return self.func(*args, **kwargs)
           ^^^^^^^^^^^^^^^^^^^^^^^^^^
  File "/opt/airflow/dags/open_weather_dag.py", line 35, in extract_data
    data = extract_data()
           ^^^^^^^^^^^^^^
  File "/opt/airflow/dags/open_weather_dag.py", line 35, in extract_data
    data = extract_data()
           ^^^^^^^^^^^^^^
  File "/opt/airflow/dags/open_weather_dag.py", line 35, in extract_data
    data = extract_data()
           ^^^^^^^^^^^^^^
  [Previous line repeated 922 more times]
  File "/opt/airflow/dags/open_weather_dag.py", line 34, in extract_data
    logger.info('Starting extraction...')
  File "/usr/local/lib/python3.12/logging/__init__.py", line 1539, in info
    self._log(INFO, msg, args, **kwargs)
  File "/usr/local/lib/python3.12/logging/__init__.py", line 1682, in _log
    record = self.makeRecord(self.name, level, fn, lno, msg, args,
             ^^^^^^^^^^^^^^^^^^^^^^^^^^^^^^^^^^^^^^^^^^^^^^^^^^^^^
  File "/usr/local/lib/python3.12/logging/__init__.py", line 1651, in makeRecord
    rv = _logRecordFactory(name, level, fn, lno, msg, args, exc_info, func,
         ^^^^^^^^^^^^^^^^^^^^^^^^^^^^^^^^^^^^^^^^^^^^^^^^^^^^^^^^^^^^^^^^^^
  File "/usr/local/lib/python3.12/logging/__init__.py", line 332, in __init__
    self.filename = os.path.basename(pathname)
                    ^^^^^^^^^^^^^^^^^^^^^^^^^^
  File "<frozen posixpath>", line 172, in basename
RecursionError: maximum recursion depth exceeded
[2025-03-14T18:20:55.898+0000] {local_task_job_runner.py:266} INFO - Task exited with return code 1
[2025-03-14T18:20:55.906+0000] {taskinstance.py:3901} INFO - 0 downstream tasks scheduled from follow-on schedule check
[2025-03-14T18:20:55.906+0000] {local_task_job_runner.py:245} INFO - ::endgroup::
